Workbook

Sheet Executive Summary

Sheet Cohort Retention & LTV
C6: Retention Rate Avg | D6: Month Index
C7: Cohort Month | D7: 0 | E7: 1 | F7: 2 | G7: 3 | H7: 4 | I7: 5
C8: 43313 | D8: 1
C9: 43282 | D9: 1 | E9: 0.0052
C10: 43252 | D10: 1 | E10: 0.0043 | F10: 0.0027
C11: 43221 | D11: 1 | E11: 0.0052 | F11: 0.0026 | G11: 0.0018
C12: 43191 | D12: 1 | E12: 0.0059 | F12: 0.003 | G12: 0.0024 | H12: 0.0014
C13: 43160 | D13: 1 | E13: 0.004 | F13: 0.003 | G13: 0.003 | H13: 0.0012 | I13: 0.0012
C14: 43132 | D14: 1 | E14: 0.0035 | F14: 0.004 | G14: 0.003 | H14: 0.0025 | I14: 0.0022
C15: 43101 | D15: 1 | E15: 0.0034 | F15: 0.0037 | G15: 0.0029 | H15: 0.0029 | I15: 0.0016
C16: 43070 | D16: 1 | E16: 0.0021 | F16: 0.0028 | G16: 0.0034 | H16: 0.0026 | I16: 0.0021
C17: 43040 | D17: 1 | E17: 0.0057 | F17: 0.0037 | G17: 0.0017 | H17: 0.0017 | I17: 0.0018
C18: 43009 | D18: 1 | E18: 0.0072 | F18: 0.0025 | G18: 0.0009 | H18: 0.0023 | I18: 0.0021
C19: 42979 | D19: 1 | E19: 0.007 | F19: 0.0055 | G19: 0.0027 | H19: 0.0045 | I19: 0.0022
C20: 42948 | D20: 1 | E20: 0.0069 | F20: 0.0035 | G20: 0.0027 | H20: 0.0035 | I20: 0.0052
C21: 42917 | D21: 1 | E21: 0.0053 | F21: 0.0035 | G21: 0.0024 | H21: 0.0029 | I21: 0.0021
C22: 42887 | D22: 1 | E22: 0.0049 | F22: 0.004 | G22: 0.0043 | H22: 0.003 | I22: 0.004
C23: 42856 | D23: 1 | E23: 0.0046 | F23: 0.0046 | G23: 0.0029 | H23: 0.0029 | I23: 0.0032
C24: 42826 | D24: 1 | E24: 0.0062 | F24: 0.0022 | G24: 0.0018 | H24: 0.0027 | I24: 0.0027
... C27: 42736 | D27: 1 | E27: 0.0028 | F27: 0.0028 | G27: 0.0014 | H27: 0.0042 | I27: 0.0014

Sheet Category Portfolio & Mix

Sheet Geo & CX Impact
B4: Total Orders | C4: Customer
B5: Seller | C5: SP | D5: RJ | E5: MG | F5: RS | G5: PR | H5: SC | I5: BA | J5: DF | K5: ES | L5: GO
B6: SP | C6: 31334 | D6: 8435 | E6: 7569 | F6: 3656 | G6: 3167 | H6: 2364 | I6: 2384 | J6: 1412 | K6: 1490 | L6: 1460
B7: MG | C7: 2627 | D7: 1192 | E7: 1563 | F7: 282 | G7: 367 | H7: 258 | I7: 379 | J7: 193 | K7: 180 | L7: 155
B8: PR | C8: 3004 | D8: 1002 | E8: 837 | F8: 594 | G8: 724 | H8: 397 | I8: 147 | J8: 151 | K8: 108 | L8: 90
B9: RJ | C9: 1369 | D9: 979 | E9: 562 | F9: 207 | G9: 206 | H9: 117 | I9: 138 | J9: 102 | K9: 100 | L9: 108
B10: SC | C10: 1342 | D10: 481 | E10: 439 | F10: 298 | G10: 287 | H10: 265 | I10: 84 | J10: 70 | K10: 52 | L10: 56
B11: RS | C11: 682 | D11: 247 | E11: 190 | F11: 290 | G11: 142 | H11: 119 | I11: 42 | J11: 49 | K11: 24 | L11: 23
B12: DF | C12: 314 | D12: 101 | E12: 101 | F12: 22 | G12: 28 | H12: 21 | I12: 36 | J12: 50 | K12: 19 | L12: 30
B13: BA | C13: 141 | D13: 85 | E13: 53 | F13: 22 | G13: 11 | H13: 16 | I13: 70 | J13: 17 | K13: 11 | L13: 8
B14: GO | C14: 130 | D14: 58 | E14: 85 | F14: 13 | G14: 9 | H14: 10 | I14: 8 | J14: 29 | K14: 5 | L14: 31
B15: PE | C15: 105 | D15: 43 | E15: 62 | F15: 13 | G15: 9 | H15: 9 | I15: 26 | J15: 16 | K15: 17 | L15: 12
F24: Repeat Rate | G24: Delivery
F25: Review Tier | G25: On-Time | H25: Late | I25: Repeat Lift
F26: high_4_5 | G26: 0.0206 | H26: 0.0212 | I26: =(GETPIVOTDATA("repeat_rate_90d",$F$24,"Delivery","Late","Review Tier","high_4_5")-GETPIVOTDATA("repeat_rate_90d",$F$24,"Delivery","On-Time","Review Tier","high_4_5")) / GETPIVOTDATA("repeat_rate_90d",$F$24,"Delivery","On-Time","Review Tier","high_4_5") -> 0.029126214
F27: low_1_2 | G27: 0.0266 | H27: 0.0163 | I27: =(GETPIVOTDATA("repeat_rate_90d",$F$24,"Delivery","Late","Review Tier","low_1_2")-GETPIVOTDATA("repeat_rate_90d",$F$24,"Delivery","On-Time","Review Tier","low_1_2"))/GETPIVOTDATA("repeat_rate_90d",$F$24,"Delivery","On-Time","Review Tier","low_1_2") -> -0.38721805
F28: mid_3 | G28: 0.0215 | H28: 0.0266 | I28: =(GETPIVOTDATA("repeat_rate_90d",$F$24,"Delivery","Late","Review Tier","mid_3")-GETPIVOTDATA("repeat_rate_90d",$F$24,"Delivery","On-Time","Review Tier","mid_3"))/GETPIVOTDATA("repeat_rate_90d",$F$24,"Delivery","On-Time","Review Tier","mid_3") -> 0.2372093

Sheet cohort_ltv_month
A1: cohort_month | B1: month_index | C1: cohort_size | D1: active_customers | E1: orders | F1: gross_revenue | G1: retention_rate | H1: revenue_per_cohort_customer | I1: cumulative_revenue_per_cohort_customer
A2: 42614 | B2: 0 | C2: 1 | D2: 1 | E2: 1 | F2: 143.46 | G2: 1 | H2: 143.46 | I2: 143.46
A3: 42644 | B3: 0 | C3: 262 | D3: 262 | E3: 265 | F3: 46490.66 | G3: 1 | H3: 177.45 | I3: 177.45
A4: 42644 | B4: 6 | C4: 262 | D4: 1 | E4: 1 | F4: 111.3 | G4: 0.0038 | H4: 0.42 | I4: 177.87
A5: 42644 | B5: 9 | C5: 262 | D5: 1 | E5: 1 | F5: 356.13 | G5: 0.0038 | H5: 1.36 | I5: 179.23
A6: 42644 | B6: 11 | C6: 262 | D6: 1 | E6: 1 | F6: 56.78 | G6: 0.0038 | H6: 0.22 | I6: 179.45
A7: 42644 | B7: 13 | C7: 262 | D7: 1 | E7: 1 | F7: 163.53 | G7: 0.0038 | H7: 0.62 | I7: 180.07
A8: 42644 | B8: 15 | C8: 262 | D8: 1 | E8: 1 | F8: 381 | G8: 0.0038 | H8: 1.45 | I8: 181.52
A9: 42644 | B9: 17 | C9: 262 | D9: 1 | E9: 1 | F9: 116.57 | G9: 0.0038 | H9: 0.44 | I9: 181.97
A10: 42644 | B10: 19 | C10: 262 | D10: 2 | E10: 2 | F10: 384.01 | G10: 0.0076 | H10: 1.47 | I10: 183.44
A11: 42644 | B11: 20 | C11: 262 | D11: 2 | E11: 2 | F11: 181.37 | G11: 0.0076 | H11: 0.69 | I11: 184.13
A12: 42705 | B12: 0 | C12: 1 | D12: 1 | E12: 1 | F12: 19.62 | G12: 1 | H12: 19.62 | I12: 19.62
A13: 42705 | B13: 1 | C13: 1 | D13: 1 | E13: 1 | F13: 19.62 | G13: 1 | H13: 19.62 | I13: 39.24
... A220: 43313 | B220: 0 | C220: 6144 | D220: 6144 | E220: 6180 | F220: 963030.33 | G220: 1 | H220: 156.74 | I220: 156.74

Sheet geo_flows
A1: week_start | B1: seller_state | C1: customer_state | D1: orders | E1: gross_revenue | F1: aov_proxy | G1: delivered_orders | H1: reviewed_orders | I1: avg_delivery_days | J1: late_delivery_rate | K1: avg_review_score | L1: lane | M1: is_instrastate
A2: 42737 | B2: PR | C2: MG | D2: 1 | E2: 389.43 | F2: 389.43 | G2: 1 | H2: 1 | I2: 11 | J2: 0 | K2: 5 | L2: PR -> MG | M2: FALSE
A3: 42737 | B3: PR | C3: PR | D3: 29 | E3: 539.98 | F3: 18.62 | G3: 29 | H3: 29 | I3: 11.14 | J3: 0 | K3: 5 | L3: PR -> PR | M3: TRUE
A4: 42737 | B4: PR | C4: SC | D4: 1 | E4: 256.79 | F4: 256.79 | G4: 1 | H4: 1 | I4: 9 | J4: 0 | K4: 5 | L4: PR -> SC | M4: FALSE
A5: 42737 | B5: PR | C5: SP | D5: 1 | E5: 24.42 | F5: 24.42 | G5: 1 | H5: 1 | I5: 7 | J5: 0 | K5: 5 | L5: PR -> SP | M5: FALSE
A6: 42737 | B6: RJ | C6: MG | D6: 1 | E6: 175.28 | F6: 175.28 | G6: 1 | H6: 1 | I6: 7 | J6: 0 | K6: 5 | L6: RJ -> MG | M6: FALSE
A7: 42737 | B7: SP | C7: BA | D7: 1 | E7: 91.92 | F7: 91.92 | G7: 1 | H7: 1 | I7: 8 | J7: 0 | K7: 3 | L7: SP -> BA | M7: FALSE
A8: 42737 | B8: SP | C8: ES | D8: 1 | E8: 50.95 | F8: 50.95 | G8: 1 | H8: 1 | I8: 8 | J8: 0 | K8: 4 | L8: SP -> ES | M8: FALSE
A9: 42737 | B9: SP | C9: MG | D9: 1 | E9: 124.84 | F9: 124.84 | G9: 1 | H9: 1 | I9: 7 | J9: 0 | K9: 4 | L9: SP -> MG | M9: FALSE
A10: 42737 | B10: SP | C10: PR | D10: 1 | E10: 846.52 | F10: 846.52 | G10: 1 | H10: 1 | I10: 18 | J10: 0 | K10: 1 | L10: SP -> PR | M10: FALSE
A11: 42737 | B11: SP | C11: RJ | D11: 5 | E11: 575.68 | F11: 115.14 | G11: 3 | H11: 5 | I11: 7.67 | J11: 0 | K11: 3 | L11: SP -> RJ | M11: FALSE
A12: 42737 | B12: SP | C12: RN | D12: 1 | E12: 666.71 | F12: 666.71 | G12: 1 | H12: 1 | I12: 11 | J12: 0 | K12: 5 | L12: SP -> RN | M12: FALSE
A13: 42737 | B13: SP | C13: SP | D13: 3 | E13: 210.65 | F13: 70.22 | G13: 3 | H13: 3 | I13: 25 | J13: 0.3333 | K13: 3.67 | L13: SP -> SP | M13: TRUE
A14: 42744 | B14: BA | C14: GO | D14: 1 | E14: 366.26 | F14: 366.26 | G14: 1 | H14: 1 | I14: 33 | J14: 0 | K14: 5 | L14: BA -> GO | M14: FALSE
A15: 42744 | B15: BA | C15: SC | D15: 1 | E15: 782.74 | F15: 782.74 | G15: 0 | H15: 1 | K15: 1 | L15: BA -> SC | M15: FALSE
A16: 42744 | B16: BA | C16: SP | D16: 1 | E16: 782.34 | F16: 782.34 | G16: 0 | H16: 1 | K16: 4 | L16: BA -> SP | M16: FALSE
A17: 42744 | B17: DF | C17: MG | D17: 5 | E17: 2095.3 | F17: 419.06 | G17: 5 | H17: 5 | I17: 12.2 | J17: 0 | K17: 3 | L17: DF -> MG | M17: FALSE
A18: 42744 | B18: DF | C18: PR | D18: 1 | E18: 429.7 | F18: 429.7 | G18: 1 | H18: 1 | I18: 10 | J18: 0 | K18: 5 | L18: DF -> PR | M18: FALSE
A19: 42744 | B19: DF | C19: RJ | D19: 1 | E19: 424.04 | F19: 424.04 | G19: 1 | H19: 1 | I19: 13 | J19: 0 | K19: 3 | L19: DF -> RJ | M19: FALSE
A20: 42744 | B20: DF | C20: SP | D20: 2 | E20: 850.14 | F20: 425.07 | G20: 2 | H20: 2 | I20: 12 | J20: 0 | K20: 4.5 | L20: DF -> SP | M20: FALSE
A21: 42744 | B21: MG | C21: DF | D21: 1 | E21: 44.01 | F21: 44.01 | G21: 1 | H21: 1 | I21: 59 | J21: 1 | K21: 3 | L21: MG -> DF | M21: FALSE
A22: 42744 | B22: MG | C22: GO | D22: 1 | E22: 50.95 | F22: 50.95 | G22: 1 | H22: 1 | I22: 11 | J22: 0 | K22: 5 | L22: MG -> GO | M22: FALSE
A23: 42744 | B23: MG | C23: MG | D23: 1 | E23: 50.24 | F23: 50.24 | G23: 1 | H23: 1 | I23: 4 | J23: 0 | K23: 5 | L23: MG -> MG | M23: TRUE
A24: 42744 | B24: MG | C24: PR | D24: 1 | E24: 117.27 | F24: 117.27 | G24: 1 | H24: 1 | I24: 6 | J24: 0 | K24: 5 | L24: MG -> PR | M24: FALSE
A25: 42744 | B25: MG | C25: RJ | D25: 1 | E25: 108.12 | F25: 108.12 | G25: 1 | H25: 1 | I25: 46 | J25: 0 | K25: 1 | L25: MG -> RJ | M25: FALSE
A26: 42744 | B26: MG | C26: SP | D26: 2 | E26: 157.13 | F26: 78.57 | G26: 2 | H26: 2 | I26: 7.67 | J26: 0 | K26: 5 | L26: MG -> SP | M26: FALSE
A27: 42744 | B27: PR | C27: BA | D27: 1 | E27: 374.28 | F27: 374.28 | G27: 1 | H27: 1 | I27: 12 | J27: 0 | K27: 2 | L27: PR -> BA | M27: FALSE
A28: 42744 | B28: PR | C28: DF | D28: 2 | E28: 195.4 | F28: 97.7 | G28: 2 | H28: 2 | I28: 14.5 | J28: 0 | K28: 4.5 | L28: PR -> DF | M28: FALSE
A29: 42744 | B29: PR | C29: MG | D29: 1 | E29: 62.19 | F29: 62.19 | G29: 1 | H29: 1 | I29: 12 | J29: 0 | K29: 5 | L29: PR -> MG | M29: FALSE
A30: 42744 | B30: PR | C30: PA | D30: 1 | E30: 268.53 | F30: 268.53 | G30: 0 | H30: 1 | K30: 3 | L30: PR -> PA | M30: FALSE
A31: 42744 | B31: PR | C31: PR | D31: 2 | E31: 67.48 | F31: 33.74 | G31: 2 | H31: 2 | I31: 7 | J31: 0 | K31: 5 | L31: PR -> PR | M31: TRUE
A32: 42744 | B32: PR | C32: RJ | D32: 2 | E32: 880.43 | F32: 440.22 | G32: 2 | H32: 2 | I32: 16 | J32: 0 | K32: 1 | L32: PR -> RJ | M32: FALSE
A33: 42744 | B33: PR | C33: SC | D33: 2 | E33: 429.01 | F33: 214.51 | G33: 2 | H33: 2 | I33: 16.5 | J33: 0 | K33: 4.5 | L33: PR -> SC | M33: FALSE
A34: 42744 | B34: PR | C34: SP | D34: 2 | E34: 205.79 | F34: 102.9 | G34: 2 | H34: 2 | I34: 26 | J34: 0.5 | K34: 1 | L34: PR -> SP | M34: FALSE
A35: 42744 | B35: RJ | C35: DF | D35: 1 | E35: 54.95 | F35: 54.95 | G35: 1 | H35: 1 | I35: 16 | J35: 0 | K35: 5 | L35: RJ -> DF | M35: FALSE
A36: 42744 | B36: RJ | C36: MG | D36: 1 | E36: 367.65 | F36: 367.65 | G36: 1 | H36: 1 | I36: 4 | J36: 0 | K36: 5 | L36: RJ -> MG | M36: FALSE
A37: 42744 | B37: RS | C37: SC | D37: 1 | E37: 191.4 | F37: 191.4 | G37: 1 | H37: 1 | I37: 10 | J37: 0 | K37: 1 | L37: RS -> SC | M37: FALSE
A38: 42744 | B38: SC | C38: MG | D38: 1 | E38: 159.18 | F38: 159.18 | G38: 1 | H38: 1 | I38: 8 | J38: 0 | K38: 5 | L38: SC -> MG | M38: FALSE
A39: 42744 | B39: SC | C39: SC | D39: 1 | E39: 517.59 | F39: 517.59 | G39: 1 | H39: 1 | I39: 8 | J39: 0 | K39: 5 | L39: SC -> SC | M39: TRUE
A40: 42744 | B40: SC | C40: SP | D40: 1 | E40: 176.23 | F40: 176.23 | G40: 1 | H40: 1 | I40: 8 | J40: 0 | K40: 5 | L40: SC -> SP | M40: FALSE
...

Sheet retention_90d
A1: late_delivery | B1: review_bucket | C1: customers | D1: repeat_rate_90d
A2: FALSE | B2: no_review | C2: 469 | D2: 0.0213
A3: FALSE | B3: low_1_2 | C3: 8014 | D3: 0.0266
A4: FALSE | B4: mid_3 | C4: 6981 | D4: 0.0215
A5: FALSE | B5: high_4_5 | C5: 71445 | D5: 0.0206
A6: TRUE | B6: no_review | C6: 146 | D6: 0.0274
A7: TRUE | B7: low_1_2 | C7: 3874 | D7: 0.0163
A8: TRUE | B8: mid_3 | C8: 677 | D8: 0.0266
A9: TRUE | B9: high_4_5 | C9: 1648 | D9: 0.0212

Sheet category_trends
A1: week_start | B1: product_category_name | C1: product_category_name_english | D1: orders | E1: items | F1: gross_revenue | G1: item_revenue | H1: freight_revenue | I1: aov
A2: 42737 | B2: beleza_saude | C2: health_beauty | D2: 2 | E2: 2 | F2: 1056.14 | G2: 1006 | H2: 50.14 | I2: 503
A3: 42737 | B3: cool_stuff | C3: cool_stuff | D3: 1 | E3: 2 | F3: 846.52 | G3: 798 | H3: 48.52 | I3: 798
A4: 42737 | B4: ferramentas_jardim | C4: garden_tools | D4: 2 | E4: 2 | F4: 348.71 | G4: 304.9 | H4: 43.81 | I4: 152.45
A5: 42737 | B5: fashion_bolsas_e_acessorios | C5: fashion_bags_accessories | D5: 10 | E5: 10 | F5: 317.95 | G5: 228.09 | H5: 89.86 | I5: 22.809
A6: 42737 | B6: brinquedos | C6: toys | D6: 3 | E6: 3 | F6: 243.85 | G6: 203.79 | H6: 40.06 | I6: 67.93
A7: 42737 | B7: relogios_presentes | C7: watches_gifts | D7: 1 | E7: 1 | F7: 164.21 | G7: 149 | H7: 15.21 | I7: 149
A8: 42737 | B8: moveis_quarto | C8: furniture_bedroom | D8: 8 | E8: 8 | F8: 148.76 | G8: 73.2 | H8: 75.56 | I8: 9.15
A9: 42737 | B9: consoles_games | C9: consoles_games | D9: 1 | E9: 1 | F9: 124.84 | G9: 109.9 | H9: 14.94 | I9: 109.9
A10: 42737 | B10: pet_shop | C10: pet_shop | D10: 5 | E10: 5 | F10: 86.1 | G10: 42.5 | H10: 43.6 | I10: 8.5
A11: 42737 | B11: cama_mesa_banho | C11: bed_bath_table | D11: 1 | E11: 1 | F11: 84.59 | G11: 68.9 | H11: 15.69 | I11: 68.9
A12: 42737 | B12: moveis_decoracao | C12: furniture_decor | D12: 1 | E12: 1 | F12: 47.83 | G12: 34.9 | H12: 12.93 | I12: 34.9
A13: 42737 | B13: telefonia_fixa | C13: fixed_telephony | D13: 2 | E13: 2 | F13: 46.55 | G13: 21.48 | H13: 25.07 | I13: 10.74
... A4380: 43332 | B4380: dvds_blu_ray | C4380: dvds_blu_ray | D4380: 1 | E4380: 1 | F4380: 16.29 | G4380: 8.9 | H4380: 7.39 | I4380: 8.9

Sheet kpis_weekly
A1: week_start | B1: orders | C1: gross_revenue | D1: item_revenue | E1: freight_revenue | F1: aov | G1: order_value_incl_shipping | H1: shipping_per_order | I1: shipping_share | J1: items_per_order | K1: delivered_rate | L1: canceled_rate | M1: orders_4wk_avg | N1: revenue_4wk_avg | O1: aov_4wk_avg | P1: delivered_orders | Q1: canceled_orders
A2: 42737 | B2: 46 | C2: 3953.17 | D2: 3374.76 | E2: 578.41 | F2: 73.36 | G2: 85.94 | H2: 12.57 | I2: 0.1463 | J2: 1.02 | K2: 0.9565 | L2: 0 | M2: 21.75 | N2: 2116.55 | O2: 44.74 | P2: 43.999 | Q2: 0
A3: 42744 | B3: 80 | C3: 14742.33 | D3: 12937.24 | E3: 1805.09 | F3: 161.72 | G3: 184.28 | H3: 22.56 | I3: 0.1224 | J3: 1.11 | K3: 0.9125 | L3: 0.025 | M3: 32 | N3: 4678.78 | O3: 61.5 | P3: 73 | Q3: 2
A4: 42751 | B4: 197 | C4: 28318.24 | D4: 24310.46 | E4: 4007.78 | F4: 123.4 | G4: 143.75 | H4: 20.34 | I4: 0.1415 | J4: 1.21 | K4: 0.9594 | L4: 0 | M4: 81 | N4: 11758.34 | O4: 92.35 | P4: 189.0018 | Q4: 0
A5: 42758 | B5: 354 | C5: 65589.08 | D5: 57773.15 | E5: 7815.93 | F5: 163.2 | G5: 185.28 | H5: 22.08 | I5: 0.1192 | J5: 1.19 | K5: 0.9379 | L5: 0.0028 | M5: 169.25 | N5: 28150.71 | O5: 130.42 | P5: 332.0166 | Q5: 0.9912
A6: 42765 | B6: 467 | C6: 81927.9 | D6: 71710.34 | E6: 10217.56 | F6: 153.56 | G6: 175.43 | H6: 21.88 | I6: 0.1247 | J6: 1.12 | K6: 0.9251 | L6: 0.0086 | M6: 274.5 | N6: 47644.39 | O6: 150.47 | P6: 432.0217 | Q6: 4.0162
A7: 42772 | B7: 548 | C7: 90027.6 | D7: 78487.83 | E7: 11539.77 | F7: 143.23 | G7: 164.28 | H7: 21.06 | I7: 0.1282 | J7: 1.07 | K7: 0.9325 | L7: 0.0073 | M7: 391.5 | N7: 66465.71 | O7: 145.85 | P7: 511.01 | Q7: 4.0004
A8: 42779 | B8: 411 | C8: 63703.67 | D8: 54493.94 | E8: 9209.73 | F8: 132.59 | G8: 155 | H8: 22.41 | I8: 0.1446 | J8: 1.1 | K8: 0.9221 | L8: 0.0073 | M8: 445 | N8: 75312.06 | O8: 148.15 | P8: 378.9831 | Q8: 3.0003
A9: 42786 | B9: 379 | C9: 55800.11 | D9: 47463.29 | E9: 8336.82 | F9: 125.23 | G9: 147.23 | H9: 22 | I9: 0.1494 | J9: 1.14 | K9: 0.9208 | L9: 0.0106 | M9: 451.25 | N9: 72864.82 | O9: 138.65 | P9: 348.9832 | Q9: 4.0174
A10: 42793 | B10: 497 | C10: 83904.75 | D10: 72974.86 | E10: 10929.89 | F10: 146.83 | G10: 168.82 | H10: 21.99 | I10: 0.1303 | J10: 1.12 | K10: 0.9276 | L10: 0.0141 | M10: 458.75 | N10: 73359.03 | O10: 136.97 | P10: 461.0172 | Q10: 7.0077
A11: 42800 | B11: 582 | C11: 91402.52 | D11: 78362.16 | E11: 13040.36 | F11: 134.64 | G11: 157.05 | H11: 22.41 | I11: 0.1427 | J11: 1.14 | K11: 0.9416 | L11: 0.012 | M11: 467.25 | N11: 73702.76 | O11: 134.82 | P11: 548.0112 | Q11: 6.984
A12: 42807 | B12: 615 | C12: 108992.57 | D12: 95524.38 | E12: 13468.19 | F12: 155.32 | G12: 177.22 | H12: 21.9 | I12: 0.1236 | J12: 1.13 | K12: 0.961 | L12: 0.0081 | M12: 518.25 | N12: 85024.99 | O12: 140.51 | P12: 591.015 | Q12: 4.9815
A13: 42814 | B13: 654 | C13: 98406.84 | D13: 84932 | E13: 13474.84 | F13: 129.87 | G13: 150.47 | H13: 20.6 | I13: 0.1369 | J13: 1.11 | K13: 0.9541 | L13: 0.0168 | M13: 587 | N13: 95676.67 | O13: 141.67 | P13: 623.9814 | Q13: 10.9872
... A87: 43332 | B87: 1071 | C87: 146870.04 | D87: 126434.29 | E87: 20435.75 | F87: 118.05 | G87: 137.13 | H87: 19.08 | I87: 0.1391 | J87: 1.11 | K87: 0.9841 | L87: 0.0112 | M87: 1748 | N87: 272632.3 | O87: 131.06 | P87: 1053.9711 | Q87: 11.9952

Sheet new_vs_returning_customers
A1: week_start | B1: new_customers | C1: returning_customers | D1: new_customer_share | E1: new_customer_revenue | F1: returning_customer_revenue | G1: returning_customer_share
A2: 42737 | B2: 30 | C2: 1 | D2: 0.9677 | E2: 3933.55 | F2: 19.62 | G2: 0.032258065
A3: 42744 | B3: 77 | C3: 0 | D3: 1 | E3: 14742.33 | G3: 0
A4: 42751 | B4: 191 | C4: 0 | D4: 1 | E4: 28318.24 | G4: 0
A5: 42758 | B5: 348 | C5: 1 | D5: 0.9971 | E5: 65484.78 | F5: 104.3 | G5: 0.0028653295
A6: 42765 | B6: 459 | C6: 1 | D6: 0.9978 | E6: 81862.85 | F6: 65.05 | G6: 0.002173913
A7: 42772 | B7: 539 | C7: 2 | D7: 0.9963 | E7: 89916.53 | F7: 111.07 | G7: 0.0036968577
A8: 42779 | B8: 404 | C8: 3 | D8: 0.9926 | E8: 63365.46 | F8: 338.21 | G8: 0.0073710074
A9: 42786 | B9: 371 | C9: 4 | D9: 0.9893 | E9: 55445.07 | F9: 355.04 | G9: 0.010666667
A10: 42793 | B10: 484 | C10: 4 | D10: 0.9918 | E10: 83363.31 | F10: 541.44 | G10: 0.0081967213
A11: 42800 | B11: 572 | C11: 1 | D11: 0.9983 | E11: 91323 | F11: 79.52 | G11: 0.0017452007
A12: 42807 | B12: 610 | C12: 1 | D12: 0.9984 | E12: 108514.24 | F12: 478.33 | G12: 0.0016366612
A13: 42814 | B13: 641 | C13: 1 | D13: 0.9984 | E13: 98347.94 | F13: 58.9 | G13: 0.0015576324
A14: 42821 | B14: 554 | C14: 4 | D14: 0.9928 | E14: 98143.64 | F14: 264.99 | G14: 0.0071684588
A15: 42828 | B15: 568 | C15: 6 | D15: 0.9895 | E15: 104707.38 | F15: 1026.58 | G15: 0.010452962
A16: 42835 | B16: 435 | C16: 6 | D16: 0.9864 | E16: 68837.86 | F16: 517.41 | G16: 0.013605442
... A87: 43332 | B87: 1028 | C87: 41 | D87: 0.9616 | E87: 142427.52 | F87: 4442.52 | G87: 0.038353601

Sheet pivots
A3: Total Orders | B3: =SUM(kpis_weekly!B:B) -> 98962
A4: Gross Revenue | B4: =SUM(kpis_weekly!C:C) -> 15774208
A5: Item Revenue | B5: =SUM(kpis_weekly!D:D) -> 13531147
A6: Average AOV | B6: =B5/B3 -> 136.73073
A7: Delivered Rate | B7: =SUM(kpis_weekly!M:M) / SUM(kpis_weekly!B:B) -> 0.97749894
A8: Canceled Rate | B8: =SUM(kpis_weekly!N:N) / SUM(kpis_weekly!B:B) -> 156.0073
A14: Row Labels | B14: Sum of orders | C14: Sum of gross_revenue
A15: 2017 | B15: 45101 | C15: 7142672.4
A16: 2018 | B16: 53861 | C16: 8631535.6
A22: Row Labels | B22: Total Orders
A23: 42737 | B23: 46
A24: 42744 | B24: 80
A25: 42751 | B25: 197
A26: 42758 | B26: 354
A27: 42765 | B27: 467
A28: 42772 | B28: 548
A29: 42779 | B29: 411
A30: 42786 | B30: 379
A31: 42793 | B31: 497
A32: 42800 | B32: 582
A33: 42807 | B33: 615
A34: 42814 | B34: 654
... A108: 43332 | B108: 1071
A115: Row Labels | B115: Gross Revenue
A116: 42737 | B116: 3953.17
A117: 42744 | B117: 14742.33
A118: 42751 | B118: 28318.24
A119: 42758 | B119: 65589.08
A120: 42765 | B120: 81927.9
A121: 42772 | B121: 90027.6
A122: 42779 | B122: 63703.67
A123: 42786 | B123: 55800.11
A124: 42793 | B124: 83904.75
A125: 42800 | B125: 91402.52
A126: 42807 | B126: 108992.57
A127: 42814 | B127: 98406.84
... A201: 43332 | B201: 146870.04
A204: Row Labels | B204: Average of aov_4wk_avg
A205: 42737 | B205: 44.74
A206: 42744 | B206: 61.5
...

Sheet charts
A1: Row Labels | B1: Sum of gross_revenue
A2: garden_tools | B2: 565570.89
A3: auto | B3: 667579.1
A4: cool_stuff | B4: 690166.41
A5: housewares | B5: 755228.81
A6: furniture_decor | B6: 873214.98
A7: computers_accessories | B7: 1031406
A8: sports_leisure | B8: 1114590.7
A9: bed_bath_table | B9: 1223375.5
A10: watches_gifts | B10: 1261075.3
A11: health_beauty | B11: 1405878.3
A26: Row Labels | B26: Sum of orders
A27: toys | B27: 3777
A28: auto | B28: 3796
A29: telephony | B29: 4083
A30: watches_gifts | B30: 5486
A31: housewares | B31: 5717
A32: furniture_decor | B32: 6256
A33: computers_accessories | B33: 6512
A34: sports_leisure | B34: 7499
A35: health_beauty | B35: 8595
A36: bed_bath_table | B36: 9255
A46: Row Labels | B46: Average of aov
A47: air_conditioning | B47: 232.35892
A48: watches_gifts | B48: 243.0335
A49: construction_tools_safety | B49: 271.0893
A50: musical_instruments | B50: 294.8446
A51: small_appliances | B51: 305.77569
A52: fixed_telephony | B52: 330.0094
A53: agro_industry_and_commerce | B53: 411.13878
A54: home_appliances_2 | B54: 414.06803
A55: small_appliances_home_oven_and_coffee | B55: 764.47343
A56: computers | B56: 1282.8316
A57: Grand Total | B57: 387.84455
A68: Sum of gross_revenue | B68: Column Labels
A69: Row Labels | B69: bed_bath_table | C69: computers_accessories | D69: health_beauty | E69: sports_leisure | F69: watches_gifts
A70: 2017
A71: Jan | B71: 6957.56 | C71: 5521 | D71: 23526.65 | E71: 14472.51 | F71: 9822.87
A72: Feb | B72: 20842.77 | C72: 14841.1 | D72: 19112.31 | E72: 23285.48 | F72: 12445.32
A73: Mar | B73: 28397.11 | C73: 28707.16 | D73: 27530.44 | E73: 21582.55 | F73: 26023.89
...
